Workbook

Sheet How_to_fill
A1: HOW TO FILL THE LEDGER
A2: 1. One row = one line in the book (one visit or one payment).
A3: 2. Date: type as 02-10-2024 (day-month-year).
A4: 3. Customer_ID: use CUST_001, CUST_002 ... never the real name. Real names go only in the Customers sheet.
A5: 4. Type: pick Purchase (took goods) or Payment (gave money) from the dropdown.
A6: 5. Amount: number only, no Rs sign.
A7: 6. Written_Balance: only if dad wrote a total/balance on that line. Otherwise leave empty.
A8: 7. Page_No: the page number in the book, so any row can be checked later.
A9: 8. If a line is unreadable, type your best guess and write 'unclear' in Notes.
A11: Public copy: the customer names column has been removed from the Customers sheet.

Sheet Top_Customers
A1: Type | B1: Purchase
A3: Row Labels | B3: Sum of Amount
A4: CUST_027 | B4: 0.19996032 | D4: =SUM(B4:B8) -> 0.45863945
A5: CUST_006 | B5: 0.075351902
A6: CUST_019 | B6: 0.0700325
A7: CUST_026 | B7: 0.056812942
A8: CUST_007 | B8: 0.056481789
A9: CUST_017 | B9: 0.047822916
A10: CUST_013 | B10: 0.045120598
A11: CUST_002 | B11: 0.040313994
A12: CUST_015 | B12: 0.037888336
A13: CUST_021 | B13: 0.036549753
A14: CUST_004 | B14: 0.033524666
A15: CUST_029 | B15: 0.032666743
A16: CUST_020 | B16: 0.027699453
... A33: Grand Total | B33: 1

Sheet Customer_Summary
A1: Customer_ID | B1: Total_Bought | C1: Total_Paid | D1: Old_Balance | E1: Adjustments | F1: Owes_Now | G1: Pct_Paid | H1: Share_of_Sales | I1: Purchase_Entries | J1: Last_Purchase | K1: Customer_Type
A2: CUST_001 | B2: =SUMIFS(Table1[Amount],Table1[Customer_ID],A2,Table1[Type],"Purchase") -> 13976 | C2: =SUMIFS(Table1[Amount],Table1[Customer_ID],A2,Table1[Type],"Payment") -> 7500 | D2: =SUMIFS(Table1[Amount],Table1[Customer_ID],A2,Table1[Type],"Old_Balance") -> 3894 | E2: =SUMIFS(Table1[Amount],Table1[Customer_ID],A2,Table1[Type],"Adjustment") -> -69 | F2: =D2+B2+E2-C2 -> 10301 | G2: =IFERROR(C2/(B2+D2+E2),0) -> 0.42132464 | H2: =B2/SUM($B$2:$B$30) -> 0.019528226 | I2: =COUNTIFS(Table1[Customer_ID],A2,Table1[Type],"Purchase") -> 60 | J2: =_xlfn.MAXIFS(Table1[Date],Table1[Customer_ID],A2,Table1[Type],"Purchase") -> 45743 | K2: =_xlfn.XLOOKUP(A2,Customers!$A$2:$A$30,Customers!$C$2:$C$30,"Not found") -> Carries forward
A3: CUST_002 | B3: =SUMIFS(Table1[Amount],Table1[Customer_ID],A3,Table1[Type],"Purchase") -> 28852 | C3: =SUMIFS(Table1[Amount],Table1[Customer_ID],A3,Table1[Type],"Payment") -> 34982 | D3: =SUMIFS(Table1[Amount],Table1[Customer_ID],A3,Table1[Type],"Old_Balance") -> 5689 | E3: =SUMIFS(Table1[Amount],Table1[Customer_ID],A3,Table1[Type],"Adjustment") -> 441 | F3: =D3+B3+E3-C3 -> 0 | G3: =IFERROR(C3/(B3+D3+E3),0) -> 1 | H3: =B3/SUM($B$2:$B$30) -> 0.040313994 | I3: =COUNTIFS(Table1[Customer_ID],A3,Table1[Type],"Purchase") -> 164 | J3: =_xlfn.MAXIFS(Table1[Date],Table1[Customer_ID],A3,Table1[Type],"Purchase") -> 45759 | K3: =_xlfn.XLOOKUP(A3,Customers!$A$2:$A$30,Customers!$C$2:$C$30,"Not found") -> Pays full
A4: CUST_003 | B4: =SUMIFS(Table1[Amount],Table1[Customer_ID],A4,Table1[Type],"Purchase") -> 17955 | C4: =SUMIFS(Table1[Amount],Table1[Customer_ID],A4,Table1[Type],"Payment") -> 18000 | D4: =SUMIFS(Table1[Amount],Table1[Customer_ID],A4,Table1[Type],"Old_Balance") -> 0 | E4: =SUMIFS(Table1[Amount],Table1[Customer_ID],A4,Table1[Type],"Adjustment") -> 178 | F4: =D4+B4+E4-C4 -> 133 | G4: =IFERROR(C4/(B4+D4+E4),0) -> 0.99266531 | H4: =B4/SUM($B$2:$B$30) -> 0.025087958 | I4: =COUNTIFS(Table1[Customer_ID],A4,Table1[Type],"Purchase") -> 151 | J4: =_xlfn.MAXIFS(Table1[Date],Table1[Customer_ID],A4,Table1[Type],"Purchase") -> 44907 | K4: =_xlfn.XLOOKUP(A4,Customers!$A$2:$A$30,Customers!$C$2:$C$30,"Not found") -> Carries forward
A5: CUST_004 | B5: =SUMIFS(Table1[Amount],Table1[Customer_ID],A5,Table1[Type],"Purchase") -> 23993 | C5: =SUMIFS(Table1[Amount],Table1[Customer_ID],A5,Table1[Type],"Payment") -> 18000 | D5: =SUMIFS(Table1[Amount],Table1[Customer_ID],A5,Table1[Type],"Old_Balance") -> 320 | E5: =SUMIFS(Table1[Amount],Table1[Customer_ID],A5,Table1[Type],"Adjustment") -> -255 | F5: =D5+B5+E5-C5 -> 6058 | G5: =IFERROR(C5/(B5+D5+E5),0) -> 0.74819187 | H5: =B5/SUM($B$2:$B$30) -> 0.033524666 | I5: =COUNTIFS(Table1[Customer_ID],A5,Table1[Type],"Purchase") -> 167 | J5: =_xlfn.MAXIFS(Table1[Date],Table1[Customer_ID],A5,Table1[Type],"Purchase") -> 44997 | K5: =_xlfn.XLOOKUP(A5,Customers!$A$2:$A$30,Customers!$C$2:$C$30,"Not found") -> Carries forward
A6: CUST_005 | B6: =SUMIFS(Table1[Amount],Table1[Customer_ID],A6,Table1[Type],"Purchase") -> 4750 | C6: =SUMIFS(Table1[Amount],Table1[Customer_ID],A6,Table1[Type],"Payment") -> 3400 | D6: =SUMIFS(Table1[Amount],Table1[Customer_ID],A6,Table1[Type],"Old_Balance") -> 653 | E6: =SUMIFS(Table1[Amount],Table1[Customer_ID],A6,Table1[Type],"Adjustment") -> 9 | F6: =D6+B6+E6-C6 -> 2012 | G6: =IFERROR(C6/(B6+D6+E6),0) -> 0.62823356 | H6: =B6/SUM($B$2:$B$30) -> 0.0066370259 | I6: =COUNTIFS(Table1[Customer_ID],A6,Table1[Type],"Purchase") -> 186 | J6: =_xlfn.MAXIFS(Table1[Date],Table1[Customer_ID],A6,Table1[Type],"Purchase") -> 45026 | K6: =_xlfn.XLOOKUP(A6,Customers!$A$2:$A$30,Customers!$C$2:$C$30,"Not found") -> Carries forward
A7: CUST_006 | B7: =SUMIFS(Table1[Amount],Table1[Customer_ID],A7,Table1[Type],"Purchase") -> 53928 | C7: =SUMIFS(Table1[Amount],Table1[Customer_ID],A7,Table1[Type],"Payment") -> 48750 | D7: =SUMIFS(Table1[Amount],Table1[Customer_ID],A7,Table1[Type],"Old_Balance") -> 6954 | E7: =SUMIFS(Table1[Amount],Table1[Customer_ID],A7,Table1[Type],"Adjustment") -> -2563 | F7: =D7+B7+E7-C7 -> 9569 | G7: =IFERROR(C7/(B7+D7+E7),0) -> 0.83591968 | H7: =B7/SUM($B$2:$B$30) -> 0.075351902 | I7: =COUNTIFS(Table1[Customer_ID],A7,Table1[Type],"Purchase") -> 173 | J7: =_xlfn.MAXIFS(Table1[Date],Table1[Customer_ID],A7,Table1[Type],"Purchase") -> 45049 | K7: =_xlfn.XLOOKUP(A7,Customers!$A$2:$A$30,Customers!$C$2:$C$30,"Not found") -> Mixed
A8: CUST_007 | B8: =SUMIFS(Table1[Amount],Table1[Customer_ID],A8,Table1[Type],"Purchase") -> 40423 | C8: =SUMIFS(Table1[Amount],Table1[Customer_ID],A8,Table1[Type],"Payment") -> 45396 | D8: =SUMIFS(Table1[Amount],Table1[Customer_ID],A8,Table1[Type],"Old_Balance") -> 14329 | E8: =SUMIFS(Table1[Amount],Table1[Customer_ID],A8,Table1[Type],"Adjustment") -> -272 | F8: =D8+B8+E8-C8 -> 9084 | G8: =IFERROR(C8/(B8+D8+E8),0) -> 0.83325991 | H8: =B8/SUM($B$2:$B$30) -> 0.056481789 | I8: =COUNTIFS(Table1[Customer_ID],A8,Table1[Type],"Purchase") -> 101 | J8: =_xlfn.MAXIFS(Table1[Date],Table1[Customer_ID],A8,Table1[Type],"Purchase") -> 44923 | K8: =_xlfn.XLOOKUP(A8,Customers!$A$2:$A$30,Customers!$C$2:$C$30,"Not found") -> Pays full
A9: CUST_008 | B9: =SUMIFS(Table1[Amount],Table1[Customer_ID],A9,Table1[Type],"Purchase") -> 1634 | C9: =SUMIFS(Table1[Amount],Table1[Customer_ID],A9,Table1[Type],"Payment") -> 1888 | D9: =SUMIFS(Table1[Amount],Table1[Customer_ID],A9,Table1[Type],"Old_Balance") -> 259 | E9: =SUMIFS(Table1[Amount],Table1[Customer_ID],A9,Table1[Type],"Adjustment") -> -5 | F9: =D9+B9+E9-C9 -> 0 | G9: =IFERROR(C9/(B9+D9+E9),0) -> 1 | H9: =B9/SUM($B$2:$B$30) -> 0.0022831369 | I9: =COUNTIFS(Table1[Customer_ID],A9,Table1[Type],"Purchase") -> 95 | J9: =_xlfn.MAXIFS(Table1[Date],Table1[Customer_ID],A9,Table1[Type],"Purchase") -> 44934 | K9: =_xlfn.XLOOKUP(A9,Customers!$A$2:$A$30,Customers!$C$2:$C$30,"Not found") -> Carries forward
A10: CUST_009 | B10: =SUMIFS(Table1[Amount],Table1[Customer_ID],A10,Table1[Type],"Purchase") -> 634 | C10: =SUMIFS(Table1[Amount],Table1[Customer_ID],A10,Table1[Type],"Payment") -> 0 | D10: =SUMIFS(Table1[Amount],Table1[Customer_ID],A10,Table1[Type],"Old_Balance") -> 197 | E10: =SUMIFS(Table1[Amount],Table1[Customer_ID],A10,Table1[Type],"Adjustment") -> 0 | F10: =D10+B10+E10-C10 -> 831 | G10: =IFERROR(C10/(B10+D10+E10),0) -> 0 | H10: =B10/SUM($B$2:$B$30) -> 0.0008858683 | I10: =COUNTIFS(Table1[Customer_ID],A10,Table1[Type],"Purchase") -> 17 | J10: =_xlfn.MAXIFS(Table1[Date],Table1[Customer_ID],A10,Table1[Type],"Purchase") -> 44832 | K10: =_xlfn.XLOOKUP(A10,Customers!$A$2:$A$30,Customers!$C$2:$C$30,"Not found") -> Carries forward
A11: CUST_010 | B11: =SUMIFS(Table1[Amount],Table1[Customer_ID],A11,Table1[Type],"Purchase") -> 14718 | C11: =SUMIFS(Table1[Amount],Table1[Customer_ID],A11,Table1[Type],"Payment") -> 17203 | D11: =SUMIFS(Table1[Amount],Table1[Customer_ID],A11,Table1[Type],"Old_Balance") -> 2631 | E11: =SUMIFS(Table1[Amount],Table1[Customer_ID],A11,Table1[Type],"Adjustment") -> -70 | F11: =D11+B11+E11-C11 -> 76 | G11: =IFERROR(C11/(B11+D11+E11),0) -> 0.9956016 | H11: =B11/SUM($B$2:$B$30) -> 0.020565 | I11: =COUNTIFS(Table1[Customer_ID],A11,Table1[Type],"Purchase") -> 47 | J11: =_xlfn.MAXIFS(Table1[Date],Table1[Customer_ID],A11,Table1[Type],"Purchase") -> 45084 | K11: =_xlfn.XLOOKUP(A11,Customers!$A$2:$A$30,Customers!$C$2:$C$30,"Not found") -> Mixed
A12: CUST_011 | B12: =SUMIFS(Table1[Amount],Table1[Customer_ID],A12,Table1[Type],"Purchase") -> 12074 | C12: =SUMIFS(Table1[Amount],Table1[Customer_ID],A12,Table1[Type],"Payment") -> 14571 | D12: =SUMIFS(Table1[Amount],Table1[Customer_ID],A12,Table1[Type],"Old_Balance") -> 2508 | E12: =SUMIFS(Table1[Amount],Table1[Customer_ID],A12,Table1[Type],"Adjustment") -> -11 | F12: =D12+B12+E12-C12 -> 0 | G12: =IFERROR(C12/(B12+D12+E12),0) -> 1 | H12: =B12/SUM($B$2:$B$30) -> 0.016870621 | I12: =COUNTIFS(Table1[Customer_ID],A12,Table1[Type],"Purchase") -> 97 | J12: =_xlfn.MAXIFS(Table1[Date],Table1[Customer_ID],A12,Table1[Type],"Purchase") -> 45025 | K12: =_xlfn.XLOOKUP(A12,Customers!$A$2:$A$30,Customers!$C$2:$C$30,"Not found") -> Pays full
A13: CUST_012 | B13: =SUMIFS(Table1[Amount],Table1[Customer_ID],A13,Table1[Type],"Purchase") -> 1965 | C13: =SUMIFS(Table1[Amount],Table1[Customer_ID],A13,Table1[Type],"Payment") -> 2500 | D13: =SUMIFS(Table1[Amount],Table1[Customer_ID],A13,Table1[Type],"Old_Balance") -> 1705 | E13: =SUMIFS(Table1[Amount],Table1[Customer_ID],A13,Table1[Type],"Adjustment") -> 0 | F13: =D13+B13+E13-C13 -> 1170 | G13: =IFERROR(C13/(B13+D13+E13),0) -> 0.68119891 | H13: =B13/SUM($B$2:$B$30) -> 0.0027456328 | I13: =COUNTIFS(Table1[Customer_ID],A13,Table1[Type],"Purchase") -> 79 | J13: =_xlfn.MAXIFS(Table1[Date],Table1[Customer_ID],A13,Table1[Type],"Purchase") -> 45476 | K13: =_xlfn.XLOOKUP(A13,Customers!$A$2:$A$30,Customers!$C$2:$C$30,"Not found") -> Carries forward
... A30: CUST_029 | B30: =SUMIFS(Table1[Amount],Table1[Customer_ID],A30,Table1[Type],"Purchase") -> 23379 | C30: =SUMIFS(Table1[Amount],Table1[Customer_ID],A30,Table1[Type],"Payment") -> 16331 | D30: =SUMIFS(Table1[Amount],Table1[Customer_ID],A30,Table1[Type],"Old_Balance") -> 0 | E30: =SUMIFS(Table1[Amount],Table1[Customer_ID],A30,Table1[Type],"Adjustment") -> 7 | F30: =D30+B30+E30-C30 -> 7055 | G30: =IFERROR(C30/(B30+D30+E30),0) -> 0.69832378 | H30: =B30/SUM($B$2:$B$30) -> 0.032666743 | I30: =COUNTIFS(Table1[Customer_ID],A30,Table1[Type],"Purchase") -> 85 | J30: =_xlfn.MAXIFS(Table1[Date],Table1[Customer_ID],A30,Table1[Type],"Purchase") -> 45705 | K30: =_xlfn.XLOOKUP(A30,Customers!$A$2:$A$30,Customers!$C$2:$C$30,"Not found") -> Pays full
A32: TOTAL | B32: =SUM(B2:B30) -> 715682 | C32: =SUM(C2:C30) -> 694704 | D32: =SUM(D2:D30) -> 106690 | E32: =SUM(E2:E30) -> -2347 | F32: =SUM(F2:F30) -> 125321 | G32: =C32/(B32+D32+E32) -> 0.84717417 | H32: =SUM(H2:H30) -> 1 | I32: =SUM(I2:I30) -> 2755

Sheet Monthly_Visits
A1: Month | B1: CUST_001 | C1: CUST_002 | D1: CUST_003 | E1: CUST_004 | F1: CUST_005 | G1: CUST_006 | H1: CUST_007 | I1: CUST_008 | J1: CUST_009 | K1: CUST_010 | L1: CUST_011 | M1: CUST_012 | N1: CUST_013 | O1: CUST_014 | P1: CUST_015 | Q1: CUST_016 | R1: CUST_017 | S1: CUST_018 | T1: CUST_019 | U1: CUST_020 | V1: CUST_021 | W1: CUST_022 | X1: CUST_023 | Y1: CUST_024 | Z1: CUST_025 | AA1: CUST_026 | AB1: CUST_027 | AC1: CUST_028 | AD1: CUST_029 | AE1: All_Customers
A2: 2021-11 | B2: =COUNTIFS(Table1[Customer_ID],B$1,Table1[Month],$A2,Table1[Type],"Purchase") -> 0 | C2: =COUNTIFS(Table1[Customer_ID],C$1,Table1[Month],$A2,Table1[Type],"Purchase") -> 0 | D2: =COUNTIFS(Table1[Customer_ID],D$1,Table1[Month],$A2,Table1[Type],"Purchase") -> 0 | E2: =COUNTIFS(Table1[Customer_ID],E$1,Table1[Month],$A2,Table1[Type],"Purchase") -> 0 | F2: =COUNTIFS(Table1[Customer_ID],F$1,Table1[Month],$A2,Table1[Type],"Purchase") -> 0 | G2: =COUNTIFS(Table1[Customer_ID],G$1,Table1[Month],$A2,Table1[Type],"Purchase") -> 0 | H2: =COUNTIFS(Table1[Customer_ID],H$1,Table1[Month],$A2,Table1[Type],"Purchase") -> 0 | I2: =COUNTIFS(Table1[Customer_ID],I$1,Table1[Month],$A2,Table1[Type],"Purchase") -> 0 | ... AD2: =COUNTIFS(Table1[Customer_ID],AD$1,Table1[Month],$A2,Table1[Type],"Purchase") -> 0 | AE2: =SUM(B2:AD2) -> 2
A3: 2021-12 | B3: =COUNTIFS(Table1[Customer_ID],B$1,Table1[Month],$A3,Table1[Type],"Purchase") -> 0 | C3: =COUNTIFS(Table1[Customer_ID],C$1,Table1[Month],$A3,Table1[Type],"Purchase") -> 0 | D3: =COUNTIFS(Table1[Customer_ID],D$1,Table1[Month],$A3,Table1[Type],"Purchase") -> 0 | E3: =COUNTIFS(Table1[Customer_ID],E$1,Table1[Month],$A3,Table1[Type],"Purchase") -> 0 | F3: =COUNTIFS(Table1[Customer_ID],F$1,Table1[Month],$A3,Table1[Type],"Purchase") -> 0 | G3: =COUNTIFS(Table1[Customer_ID],G$1,Table1[Month],$A3,Table1[Type],"Purchase") -> 0 | H3: =COUNTIFS(Table1[Customer_ID],H$1,Table1[Month],$A3,Table1[Type],"Purchase") -> 0 | I3: =COUNTIFS(Table1[Customer_ID],I$1,Table1[Month],$A3,Table1[Type],"Purchase") -> 0 | ... AD3: =COUNTIFS(Table1[Customer_ID],AD$1,Table1[Month],$A3,Table1[Type],"Purchase") -> 0 | AE3: =SUM(B3:AD3) -> 1
A4: 2022-01 | B4: =COUNTIFS(Table1[Customer_ID],B$1,Table1[Month],$A4,Table1[Type],"Purchase") -> 0 | C4: =COUNTIFS(Table1[Customer_ID],C$1,Table1[Month],$A4,Table1[Type],"Purchase") -> 0 | D4: =COUNTIFS(Table1[Customer_ID],D$1,Table1[Month],$A4,Table1[Type],"Purchase") -> 0 | E4: =COUNTIFS(Table1[Customer_ID],E$1,Table1[Month],$A4,Table1[Type],"Purchase") -> 0 | F4: =COUNTIFS(Table1[Customer_ID],F$1,Table1[Month],$A4,Table1[Type],"Purchase") -> 0 | G4: =COUNTIFS(Table1[Customer_ID],G$1,Table1[Month],$A4,Table1[Type],"Purchase") -> 0 | H4: =COUNTIFS(Table1[Customer_ID],H$1,Table1[Month],$A4,Table1[Type],"Purchase") -> 0 | I4: =COUNTIFS(Table1[Customer_ID],I$1,Table1[Month],$A4,Table1[Type],"Purchase") -> 0 | ... AD4: =COUNTIFS(Table1[Customer_ID],AD$1,Table1[Month],$A4,Table1[Type],"Purchase") -> 0 | AE4: =SUM(B4:AD4) -> 3
A5: 2022-02 | B5: =COUNTIFS(Table1[Customer_ID],B$1,Table1[Month],$A5,Table1[Type],"Purchase") -> 0 | C5: =COUNTIFS(Table1[Customer_ID],C$1,Table1[Month],$A5,Table1[Type],"Purchase") -> 0 | D5: =COUNTIFS(Table1[Customer_ID],D$1,Table1[Month],$A5,Table1[Type],"Purchase") -> 0 | E5: =COUNTIFS(Table1[Customer_ID],E$1,Table1[Month],$A5,Table1[Type],"Purchase") -> 0 | F5: =COUNTIFS(Table1[Customer_ID],F$1,Table1[Month],$A5,Table1[Type],"Purchase") -> 0 | G5: =COUNTIFS(Table1[Customer_ID],G$1,Table1[Month],$A5,Table1[Type],"Purchase") -> 0 | H5: =COUNTIFS(Table1[Customer_ID],H$1,Table1[Month],$A5,Table1[Type],"Purchase") -> 0 | I5: =COUNTIFS(Table1[Customer_ID],I$1,Table1[Month],$A5,Table1[Type],"Purchase") -> 0 | ... AD5: =COUNTIFS(Table1[Customer_ID],AD$1,Table1[Month],$A5,Table1[Type],"Purchase") -> 0 | AE5: =SUM(B5:AD5) -> 0
A6: 2022-03 | B6: =COUNTIFS(Table1[Customer_ID],B$1,Table1[Month],$A6,Table1[Type],"Purchase") -> 0 | C6: =COUNTIFS(Table1[Customer_ID],C$1,Table1[Month],$A6,Table1[Type],"Purchase") -> 0 | D6: =COUNTIFS(Table1[Customer_ID],D$1,Table1[Month],$A6,Table1[Type],"Purchase") -> 0 | E6: =COUNTIFS(Table1[Customer_ID],E$1,Table1[Month],$A6,Table1[Type],"Purchase") -> 0 | F6: =COUNTIFS(Table1[Customer_ID],F$1,Table1[Month],$A6,Table1[Type],"Purchase") -> 0 | G6: =COUNTIFS(Table1[Customer_ID],G$1,Table1[Month],$A6,Table1[Type],"Purchase") -> 0 | H6: =COUNTIFS(Table1[Customer_ID],H$1,Table1[Month],$A6,Table1[Type],"Purchase") -> 0 | I6: =COUNTIFS(Table1[Customer_ID],I$1,Table1[Month],$A6,Table1[Type],"Purchase") -> 0 | ... AD6: =COUNTIFS(Table1[Customer_ID],AD$1,Table1[Month],$A6,Table1[Type],"Purchase") -> 0 | AE6: =SUM(B6:AD6) -> 5
A7: 2022-04 | B7: =COUNTIFS(Table1[Customer_ID],B$1,Table1[Month],$A7,Table1[Type],"Purchase") -> 0 | C7: =COUNTIFS(Table1[Customer_ID],C$1,Table1[Month],$A7,Table1[Type],"Purchase") -> 0 | D7: =COUNTIFS(Table1[Customer_ID],D$1,Table1[Month],$A7,Table1[Type],"Purchase") -> 0 | E7: =COUNTIFS(Table1[Customer_ID],E$1,Table1[Month],$A7,Table1[Type],"Purchase") -> 0 | F7: =COUNTIFS(Table1[Customer_ID],F$1,Table1[Month],$A7,Table1[Type],"Purchase") -> 0 | G7: =COUNTIFS(Table1[Customer_ID],G$1,Table1[Month],$A7,Table1[Type],"Purchase") -> 0 | H7: =COUNTIFS(Table1[Customer_ID],H$1,Table1[Month],$A7,Table1[Type],"Purchase") -> 0 | I7: =COUNTIFS(Table1[Customer_ID],I$1,Table1[Month],$A7,Table1[Type],"Purchase") -> 0 | ... AD7: =COUNTIFS(Table1[Customer_ID],AD$1,Table1[Month],$A7,Table1[Type],"Purchase") -> 0 | AE7: =SUM(B7:AD7) -> 2
A8: 2022-05 | B8: =COUNTIFS(Table1[Customer_ID],B$1,Table1[Month],$A8,Table1[Type],"Purchase") -> 0 | C8: =COUNTIFS(Table1[Customer_ID],C$1,Table1[Month],$A8,Table1[Type],"Purchase") -> 0 | D8: =COUNTIFS(Table1[Customer_ID],D$1,Table1[Month],$A8,Table1[Type],"Purchase") -> 0 | E8: =COUNTIFS(Table1[Customer_ID],E$1,Table1[Month],$A8,Table1[Type],"Purchase") -> 0 | F8: =COUNTIFS(Table1[Customer_ID],F$1,Table1[Month],$A8,Table1[Type],"Purchase") -> 0 | G8: =COUNTIFS(Table1[Customer_ID],G$1,Table1[Month],$A8,Table1[Type],"Purchase") -> 0 | H8: =COUNTIFS(Table1[Customer_ID],H$1,Table1[Month],$A8,Table1[Type],"Purchase") -> 0 | I8: =COUNTIFS(Table1[Customer_ID],I$1,Table1[Month],$A8,Table1[Type],"Purchase") -> 0 | ... AD8: =COUNTIFS(Table1[Customer_ID],AD$1,Table1[Month],$A8,Table1[Type],"Purchase") -> 0 | AE8: =SUM(B8:AD8) -> 5
A9: 2022-06 | B9: =COUNTIFS(Table1[Customer_ID],B$1,Table1[Month],$A9,Table1[Type],"Purchase") -> 0 | C9: =COUNTIFS(Table1[Customer_ID],C$1,Table1[Month],$A9,Table1[Type],"Purchase") -> 0 | D9: =COUNTIFS(Table1[Customer_ID],D$1,Table1[Month],$A9,Table1[Type],"Purchase") -> 0 | E9: =COUNTIFS(Table1[Customer_ID],E$1,Table1[Month],$A9,Table1[Type],"Purchase") -> 0 | F9: =COUNTIFS(Table1[Customer_ID],F$1,Table1[Month],$A9,Table1[Type],"Purchase") -> 0 | G9: =COUNTIFS(Table1[Customer_ID],G$1,Table1[Month],$A9,Table1[Type],"Purchase") -> 0 | H9: =COUNTIFS(Table1[Customer_ID],H$1,Table1[Month],$A9,Table1[Type],"Purchase") -> 0 | I9: =COUNTIFS(Table1[Customer_ID],I$1,Table1[Month],$A9,Table1[Type],"Purchase") -> 0 | ... AD9: =COUNTIFS(Table1[Customer_ID],AD$1,Table1[Month],$A9,Table1[Type],"Purchase") -> 0 | AE9: =SUM(B9:AD9) -> 1
A10: 2022-07 | B10: =COUNTIFS(Table1[Customer_ID],B$1,Table1[Month],$A10,Table1[Type],"Purchase") -> 0 | C10: =COUNTIFS(Table1[Customer_ID],C$1,Table1[Month],$A10,Table1[Type],"Purchase") -> 0 | D10: =COUNTIFS(Table1[Customer_ID],D$1,Table1[Month],$A10,Table1[Type],"Purchase") -> 0 | E10: =COUNTIFS(Table1[Customer_ID],E$1,Table1[Month],$A10,Table1[Type],"Purchase") -> 0 | F10: =COUNTIFS(Table1[Customer_ID],F$1,Table1[Month],$A10,Table1[Type],"Purchase") -> 0 | G10: =COUNTIFS(Table1[Customer_ID],G$1,Table1[Month],$A10,Table1[Type],"Purchase") -> 0 | H10: =COUNTIFS(Table1[Customer_ID],H$1,Table1[Month],$A10,Table1[Type],"Purchase") -> 0 | I10: =COUNTIFS(Table1[Customer_ID],I$1,Table1[Month],$A10,Table1[Type],"Purchase") -> 0 | ... AD10: =COUNTIFS(Table1[Customer_ID],AD$1,Table1[Month],$A10,Table1[Type],"Purchase") -> 0 | AE10: =SUM(B10:AD10) -> 0
A11: 2022-08 | B11: =COUNTIFS(Table1[Customer_ID],B$1,Table1[Month],$A11,Table1[Type],"Purchase") -> 0 | C11: =COUNTIFS(Table1[Customer_ID],C$1,Table1[Month],$A11,Table1[Type],"Purchase") -> 0 | D11: =COUNTIFS(Table1[Customer_ID],D$1,Table1[Month],$A11,Table1[Type],"Purchase") -> 0 | E11: =COUNTIFS(Table1[Customer_ID],E$1,Table1[Month],$A11,Table1[Type],"Purchase") -> 0 | F11: =COUNTIFS(Table1[Customer_ID],F$1,Table1[Month],$A11,Table1[Type],"Purchase") -> 0 | G11: =COUNTIFS(Table1[Customer_ID],G$1,Table1[Month],$A11,Table1[Type],"Purchase") -> 0 | H11: =COUNTIFS(Table1[Customer_ID],H$1,Table1[Month],$A11,Table1[Type],"Purchase") -> 0 | I11: =COUNTIFS(Table1[Customer_ID],I$1,Table1[Month],$A11,Table1[Type],"Purchase") -> 0 | ... AD11: =COUNTIFS(Table1[Customer_ID],AD$1,Table1[Month],$A11,Table1[Type],"Purchase") -> 0 | AE11: =SUM(B11:AD11) -> 0
A12: 2022-09 | B12: =COUNTIFS(Table1[Customer_ID],B$1,Table1[Month],$A12,Table1[Type],"Purchase") -> 0 | C12: =COUNTIFS(Table1[Customer_ID],C$1,Table1[Month],$A12,Table1[Type],"Purchase") -> 0 | D12: =COUNTIFS(Table1[Customer_ID],D$1,Table1[Month],$A12,Table1[Type],"Purchase") -> 11 | E12: =COUNTIFS(Table1[Customer_ID],E$1,Table1[Month],$A12,Table1[Type],"Purchase") -> 8 | F12: =COUNTIFS(Table1[Customer_ID],F$1,Table1[Month],$A12,Table1[Type],"Purchase") -> 0 | G12: =COUNTIFS(Table1[Customer_ID],G$1,Table1[Month],$A12,Table1[Type],"Purchase") -> 13 | H12: =COUNTIFS(Table1[Customer_ID],H$1,Table1[Month],$A12,Table1[Type],"Purchase") -> 18 | I12: =COUNTIFS(Table1[Customer_ID],I$1,Table1[Month],$A12,Table1[Type],"Purchase") -> 14 | ... AD12: =COUNTIFS(Table1[Customer_ID],AD$1,Table1[Month],$A12,Table1[Type],"Purchase") -> 0 | AE12: =SUM(B12:AD12) -> 213
A13: 2022-10 | B13: =COUNTIFS(Table1[Customer_ID],B$1,Table1[Month],$A13,Table1[Type],"Purchase") -> 0 | C13: =COUNTIFS(Table1[Customer_ID],C$1,Table1[Month],$A13,Table1[Type],"Purchase") -> 0 | D13: =COUNTIFS(Table1[Customer_ID],D$1,Table1[Month],$A13,Table1[Type],"Purchase") -> 70 | E13: =COUNTIFS(Table1[Customer_ID],E$1,Table1[Month],$A13,Table1[Type],"Purchase") -> 23 | F13: =COUNTIFS(Table1[Customer_ID],F$1,Table1[Month],$A13,Table1[Type],"Purchase") -> 9 | G13: =COUNTIFS(Table1[Customer_ID],G$1,Table1[Month],$A13,Table1[Type],"Purchase") -> 16 | H13: =COUNTIFS(Table1[Customer_ID],H$1,Table1[Month],$A13,Table1[Type],"Purchase") -> 31 | I13: =COUNTIFS(Table1[Customer_ID],I$1,Table1[Month],$A13,Table1[Type],"Purchase") -> 26 | ... AD13: =COUNTIFS(Table1[Customer_ID],AD$1,Table1[Month],$A13,Table1[Type],"Purchase") -> 0 | AE13: =SUM(B13:AD13) -> 337
... A43: 2025-04 | B43: =COUNTIFS(Table1[Customer_ID],B$1,Table1[Month],$A43,Table1[Type],"Purchase") -> 0 | C43: =COUNTIFS(Table1[Customer_ID],C$1,Table1[Month],$A43,Table1[Type],"Purchase") -> 13 | D43: =COUNTIFS(Table1[Customer_ID],D$1,Table1[Month],$A43,Table1[Type],"Purchase") -> 0 | E43: =COUNTIFS(Table1[Customer_ID],E$1,Table1[Month],$A43,Table1[Type],"Purchase") -> 0 | F43: =COUNTIFS(Table1[Customer_ID],F$1,Table1[Month],$A43,Table1[Type],"Purchase") -> 0 | G43: =COUNTIFS(Table1[Customer_ID],G$1,Table1[Month],$A43,Table1[Type],"Purchase") -> 0 | H43: =COUNTIFS(Table1[Customer_ID],H$1,Table1[Month],$A43,Table1[Type],"Purchase") -> 0 | I43: =COUNTIFS(Table1[Customer_ID],I$1,Table1[Month],$A43,Table1[Type],"Purchase") -> 0 | ... AD43: =COUNTIFS(Table1[Customer_ID],AD$1,Table1[Month],$A43,Table1[Type],"Purchase") -> 0 | AE43: =SUM(B43:AD43) -> 13
A44: TOTAL | B44: =SUM(B2:B43) -> 60 | C44: =SUM(C2:C43) -> 164 | D44: =SUM(D2:D43) -> 151 | E44: =SUM(E2:E43) -> 167 | F44: =SUM(F2:F43) -> 186 | G44: =SUM(G2:G43) -> 173 | H44: =SUM(H2:H43) -> 101 | I44: =SUM(I2:I43) -> 95 | ... AD44: =SUM(AD2:AD43) -> 85 | AE44: =SUM(B44:AD44) -> 2755

Sheet Monthly_Purchases
A1: Month | B1: CUST_001 | C1: CUST_002 | D1: CUST_003 | E1: CUST_004 | F1: CUST_005 | G1: CUST_006 | H1: CUST_007 | I1: CUST_008 | J1: CUST_009 | K1: CUST_010 | L1: CUST_011 | M1: CUST_012 | N1: CUST_013 | O1: CUST_014 | P1: CUST_015 | Q1: CUST_016 | R1: CUST_017 | S1: CUST_018 | T1: CUST_019 | U1: CUST_020 | V1: CUST_021 | W1: CUST_022 | X1: CUST_023 | Y1: CUST_024 | Z1: CUST_025 | AA1: CUST_026 | AB1: CUST_027 | AC1: CUST_028 | AD1: CUST_029 | AE1: All_Customers
A2: 2021-11 | B2: =SUMIFS(Table1[Amount],Table1[Customer_ID],B$1,Table1[Month],$A2,Table1[Type],"Purchase") -> 0 | C2: =SUMIFS(Table1[Amount],Table1[Customer_ID],C$1,Table1[Month],$A2,Table1[Type],"Purchase") -> 0 | D2: =SUMIFS(Table1[Amount],Table1[Customer_ID],D$1,Table1[Month],$A2,Table1[Type],"Purchase") -> 0 | E2: =SUMIFS(Table1[Amount],Table1[Customer_ID],E$1,Table1[Month],$A2,Table1[Type],"Purchase") -> 0 | F2: =SUMIFS(Table1[Amount],Table1[Customer_ID],F$1,Table1[Month],$A2,Table1[Type],"Purchase") -> 0 | G2: =SUMIFS(Table1[Amount],Table1[Customer_ID],G$1,Table1[Month],$A2,Table1[Type],"Purchase") -> 0 | H2: =SUMIFS(Table1[Amount],Table1[Customer_ID],H$1,Table1[Month],$A2,Table1[Type],"Purchase") -> 0 | I2: =SUMIFS(Table1[Amount],Table1[Customer_ID],I$1,Table1[Month],$A2,Table1[Type],"Purchase") -> 0 | ... AD2: =SUMIFS(Table1[Amount],Table1[Customer_ID],AD$1,Table1[Month],$A2,Table1[Type],"Purchase") -> 0 | AE2: =SUM(B2:AD2) -> 1132
A3: 2021-12 | B3: =SUMIFS(Table1[Amount],Table1[Customer_ID],B$1,Table1[Month],$A3,Table1[Type],"Purchase") -> 0 | C3: =SUMIFS(Table1[Amount],Table1[Customer_ID],C$1,Table1[Month],$A3,Table1[Type],"Purchase") -> 0 | D3: =SUMIFS(Table1[Amount],Table1[Customer_ID],D$1,Table1[Month],$A3,Table1[Type],"Purchase") -> 0 | E3: =SUMIFS(Table1[Amount],Table1[Customer_ID],E$1,Table1[Month],$A3,Table1[Type],"Purchase") -> 0 | F3: =SUMIFS(Table1[Amount],Table1[Customer_ID],F$1,Table1[Month],$A3,Table1[Type],"Purchase") -> 0 | G3: =SUMIFS(Table1[Amount],Table1[Customer_ID],G$1,Table1[Month],$A3,Table1[Type],"Purchase") -> 0 | H3: =SUMIFS(Table1[Amount],Table1[Customer_ID],H$1,Table1[Month],$A3,Table1[Type],"Purchase") -> 0 | I3: =SUMIFS(Table1[Amount],Table1[Customer_ID],I$1,Table1[Month],$A3,Table1[Type],"Purchase") -> 0 | ... AD3: =SUMIFS(Table1[Amount],Table1[Customer_ID],AD$1,Table1[Month],$A3,Table1[Type],"Purchase") -> 0 | AE3: =SUM(B3:AD3) -> 863
A4: 2022-01 | B4: =SUMIFS(Table1[Amount],Table1[Customer_ID],B$1,Table1[Month],$A4,Table1[Type],"Purchase") -> 0 | C4: =SUMIFS(Table1[Amount],Table1[Customer_ID],C$1,Table1[Month],$A4,Table1[Type],"Purchase") -> 0 | D4: =SUMIFS(Table1[Amount],Table1[Customer_ID],D$1,Table1[Month],$A4,Table1[Type],"Purchase") -> 0 | E4: =SUMIFS(Table1[Amount],Table1[Customer_ID],E$1,Table1[Month],$A4,Table1[Type],"Purchase") -> 0 | F4: =SUMIFS(Table1[Amount],Table1[Customer_ID],F$1,Table1[Month],$A4,Table1[Type],"Purchase") -> 0 | G4: =SUMIFS(Table1[Amount],Table1[Customer_ID],G$1,Table1[Month],$A4,Table1[Type],"Purchase") -> 0 | H4: =SUMIFS(Table1[Amount],Table1[Customer_ID],H$1,Table1[Month],$A4,Table1[Type],"Purchase") -> 0 | I4: =SUMIFS(Table1[Amount],Table1[Customer_ID],I$1,Table1[Month],$A4,Table1[Type],"Purchase") -> 0 | ... AD4: =SUMIFS(Table1[Amount],Table1[Customer_ID],AD$1,Table1[Month],$A4,Table1[Type],"Purchase") -> 0 | AE4: =SUM(B4:AD4) -> 911
A5: 2022-02 | B5: =SUMIFS(Table1[Amount],Table1[Customer_ID],B$1,Table1[Month],$A5,Table1[Type],"Purchase") -> 0 | C5: =SUMIFS(Table1[Amount],Table1[Customer_ID],C$1,Table1[Month],$A5,Table1[Type],"Purchase") -> 0 | D5: =SUMIFS(Table1[Amount],Table1[Customer_ID],D$1,Table1[Month],$A5,Table1[Type],"Purchase") -> 0 | E5: =SUMIFS(Table1[Amount],Table1[Customer_ID],E$1,Table1[Month],$A5,Table1[Type],"Purchase") -> 0 | F5: =SUMIFS(Table1[Amount],Table1[Customer_ID],F$1,Table1[Month],$A5,Table1[Type],"Purchase") -> 0 | G5: =SUMIFS(Table1[Amount],Table1[Customer_ID],G$1,Table1[Month],$A5,Table1[Type],"Purchase") -> 0 | H5: =SUMIFS(Table1[Amount],Table1[Customer_ID],H$1,Table1[Month],$A5,Table1[Type],"Purchase") -> 0 | I5: =SUMIFS(Table1[Amount],Table1[Customer_ID],I$1,Table1[Month],$A5,Table1[Type],"Purchase") -> 0 | ... AD5: =SUMIFS(Table1[Amount],Table1[Customer_ID],AD$1,Table1[Month],$A5,Table1[Type],"Purchase") -> 0 | AE5: =SUM(B5:AD5) -> 0
A6: 2022-03 | B6: =SUMIFS(Table1[Amount],Table1[Customer_ID],B$1,Table1[Month],$A6,Table1[Type],"Purchase") -> 0 | C6: =SUMIFS(Table1[Amount],Table1[Customer_ID],C$1,Table1[Month],$A6,Table1[Type],"Purchase") -> 0 | D6: =SUMIFS(Table1[Amount],Table1[Customer_ID],D$1,Table1[Month],$A6,Table1[Type],"Purchase") -> 0 | E6: =SUMIFS(Table1[Amount],Table1[Customer_ID],E$1,Table1[Month],$A6,Table1[Type],"Purchase") -> 0 | F6: =SUMIFS(Table1[Amount],Table1[Customer_ID],F$1,Table1[Month],$A6,Table1[Type],"Purchase") -> 0 | G6: =SUMIFS(Table1[Amount],Table1[Customer_ID],G$1,Table1[Month],$A6,Table1[Type],"Purchase") -> 0 | H6: =SUMIFS(Table1[Amount],Table1[Customer_ID],H$1,Table1[Month],$A6,Table1[Type],"Purchase") -> 0 | I6: =SUMIFS(Table1[Amount],Table1[Customer_ID],I$1,Table1[Month],$A6,Table1[Type],"Purchase") -> 0 | ... AD6: =SUMIFS(Table1[Amount],Table1[Customer_ID],AD$1,Table1[Month],$A6,Table1[Type],"Purchase") -> 0 | AE6: =SUM(B6:AD6) -> 3694
A7: 2022-04 | B7: =SUMIFS(Table1[Amount],Table1[Customer_ID],B$1,Table1[Month],$A7,Table1[Type],"Purchase") -> 0 | C7: =SUMIFS(Table1[Amount],Table1[Customer_ID],C$1,Table1[Month],$A7,Table1[Type],"Purchase") -> 0 | D7: =SUMIFS(Table1[Amount],Table1[Customer_ID],D$1,Table1[Month],$A7,Table1[Type],"Purchase") -> 0 | E7: =SUMIFS(Table1[Amount],Table1[Customer_ID],E$1,Table1[Month],$A7,Table1[Type],"Purchase") -> 0 | F7: =SUMIFS(Table1[Amount],Table1[Customer_ID],F$1,Table1[Month],$A7,Table1[Type],"Purchase") -> 0 | G7: =SUMIFS(Table1[Amount],Table1[Customer_ID],G$1,Table1[Month],$A7,Table1[Type],"Purchase") -> 0 | H7: =SUMIFS(Table1[Amount],Table1[Customer_ID],H$1,Table1[Month],$A7,Table1[Type],"Purchase") -> 0 | I7: =SUMIFS(Table1[Amount],Table1[Customer_ID],I$1,Table1[Month],$A7,Table1[Type],"Purchase") -> 0 | ... AD7: =SUMIFS(Table1[Amount],Table1[Customer_ID],AD$1,Table1[Month],$A7,Table1[Type],"Purchase") -> 0 | AE7: =SUM(B7:AD7) -> 1927
A8: 2022-05 | B8: =SUMIFS(Table1[Amount],Table1[Customer_ID],B$1,Table1[Month],$A8,Table1[Type],"Purchase") -> 0 | C8: =SUMIFS(Table1[Amount],Table1[Customer_ID],C$1,Table1[Month],$A8,Table1[Type],"Purchase") -> 0 | D8: =SUMIFS(Table1[Amount],Table1[Customer_ID],D$1,Table1[Month],$A8,Table1[Type],"Purchase") -> 0 | E8: =SUMIFS(Table1[Amount],Table1[Customer_ID],E$1,Table1[Month],$A8,Table1[Type],"Purchase") -> 0 | F8: =SUMIFS(Table1[Amount],Table1[Customer_ID],F$1,Table1[Month],$A8,Table1[Type],"Purchase") -> 0 | G8: =SUMIFS(Table1[Amount],Table1[Customer_ID],G$1,Table1[Month],$A8,Table1[Type],"Purchase") -> 0 | H8: =SUMIFS(Table1[Amount],Table1[Customer_ID],H$1,Table1[Month],$A8,Table1[Type],"Purchase") -> 0 | I8: =SUMIFS(Table1[Amount],Table1[Customer_ID],I$1,Table1[Month],$A8,Table1[Type],"Purchase") -> 0 | ... AD8: =SUMIFS(Table1[Amount],Table1[Customer_ID],AD$1,Table1[Month],$A8,Table1[Type],"Purchase") -> 0 | AE8: =SUM(B8:AD8) -> 3703
A9: 2022-06 | B9: =SUMIFS(Table1[Amount],Table1[Customer_ID],B$1,Table1[Month],$A9,Table1[Type],"Purchase") -> 0 | C9: =SUMIFS(Table1[Amount],Table1[Customer_ID],C$1,Table1[Month],$A9,Table1[Type],"Purchase") -> 0 | D9: =SUMIFS(Table1[Amount],Table1[Customer_ID],D$1,Table1[Month],$A9,Table1[Type],"Purchase") -> 0 | E9: =SUMIFS(Table1[Amount],Table1[Customer_ID],E$1,Table1[Month],$A9,Table1[Type],"Purchase") -> 0 | F9: =SUMIFS(Table1[Amount],Table1[Customer_ID],F$1,Table1[Month],$A9,Table1[Type],"Purchase") -> 0 | G9: =SUMIFS(Table1[Amount],Table1[Customer_ID],G$1,Table1[Month],$A9,Table1[Type],"Purchase") -> 0 | H9: =SUMIFS(Table1[Amount],Table1[Customer_ID],H$1,Table1[Month],$A9,Table1[Type],"Purchase") -> 0 | I9: =SUMIFS(Table1[Amount],Table1[Customer_ID],I$1,Table1[Month],$A9,Table1[Type],"Purchase") -> 0 | ... AD9: =SUMIFS(Table1[Amount],Table1[Customer_ID],AD$1,Table1[Month],$A9,Table1[Type],"Purchase") -> 0 | AE9: =SUM(B9:AD9) -> 855
A10: 2022-07 | B10: =SUMIFS(Table1[Amount],Table1[Customer_ID],B$1,Table1[Month],$A10,Table1[Type],"Purchase") -> 0 | C10: =SUMIFS(Table1[Amount],Table1[Customer_ID],C$1,Table1[Month],$A10,Table1[Type],"Purchase") -> 0 | D10: =SUMIFS(Table1[Amount],Table1[Customer_ID],D$1,Table1[Month],$A10,Table1[Type],"Purchase") -> 0 | E10: =SUMIFS(Table1[Amount],Table1[Customer_ID],E$1,Table1[Month],$A10,Table1[Type],"Purchase") -> 0 | F10: =SUMIFS(Table1[Amount],Table1[Customer_ID],F$1,Table1[Month],$A10,Table1[Type],"Purchase") -> 0 | G10: =SUMIFS(Table1[Amount],Table1[Customer_ID],G$1,Table1[Month],$A10,Table1[Type],"Purchase") -> 0 | H10: =SUMIFS(Table1[Amount],Table1[Customer_ID],H$1,Table1[Month],$A10,Table1[Type],"Purchase") -> 0 | I10: =SUMIFS(Table1[Amount],Table1[Customer_ID],I$1,Table1[Month],$A10,Table1[Type],"Purchase") -> 0 | ... AD10: =SUMIFS(Table1[Amount],Table1[Customer_ID],AD$1,Table1[Month],$A10,Table1[Type],"Purchase") -> 0 | AE10: =SUM(B10:AD10) -> 0
A11: 2022-08 | B11: =SUMIFS(Table1[Amount],Table1[Customer_ID],B$1,Table1[Month],$A11,Table1[Type],"Purchase") -> 0 | C11: =SUMIFS(Table1[Amount],Table1[Customer_ID],C$1,Table1[Month],$A11,Table1[Type],"Purchase") -> 0 | D11: =SUMIFS(Table1[Amount],Table1[Customer_ID],D$1,Table1[Month],$A11,Table1[Type],"Purchase") -> 0 | E11: =SUMIFS(Table1[Amount],Table1[Customer_ID],E$1,Table1[Month],$A11,Table1[Type],"Purchase") -> 0 | F11: =SUMIFS(Table1[Amount],Table1[Customer_ID],F$1,Table1[Month],$A11,Table1[Type],"Purchase") -> 0 | G11: =SUMIFS(Table1[Amount],Table1[Customer_ID],G$1,Table1[Month],$A11,Table1[Type],"Purchase") -> 0 | H11: =SUMIFS(Table1[Amount],Table1[Customer_ID],H$1,Table1[Month],$A11,Table1[Type],"Purchase") -> 0 | I11: =SUMIFS(Table1[Amount],Table1[Customer_ID],I$1,Table1[Month],$A11,Table1[Type],"Purchase") -> 0 | ... AD11: =SUMIFS(Table1[Amount],Table1[Customer_ID],AD$1,Table1[Month],$A11,Table1[Type],"Purchase") -> 0 | AE11: =SUM(B11:AD11) -> 0
A12: 2022-09 | B12: =SUMIFS(Table1[Amount],Table1[Customer_ID],B$1,Table1[Month],$A12,Table1[Type],"Purchase") -> 0 | C12: =SUMIFS(Table1[Amount],Table1[Customer_ID],C$1,Table1[Month],$A12,Table1[Type],"Purchase") -> 0 | D12: =SUMIFS(Table1[Amount],Table1[Customer_ID],D$1,Table1[Month],$A12,Table1[Type],"Purchase") -> 4724 | E12: =SUMIFS(Table1[Amount],Table1[Customer_ID],E$1,Table1[Month],$A12,Table1[Type],"Purchase") -> 1481 | F12: =SUMIFS(Table1[Amount],Table1[Customer_ID],F$1,Table1[Month],$A12,Table1[Type],"Purchase") -> 0 | G12: =SUMIFS(Table1[Amount],Table1[Customer_ID],G$1,Table1[Month],$A12,Table1[Type],"Purchase") -> 5036 | H12: =SUMIFS(Table1[Amount],Table1[Customer_ID],H$1,Table1[Month],$A12,Table1[Type],"Purchase") -> 9476 | I12: =SUMIFS(Table1[Amount],Table1[Customer_ID],I$1,Table1[Month],$A12,Table1[Type],"Purchase") -> 297 | ... AD12: =SUMIFS(Table1[Amount],Table1[Customer_ID],AD$1,Table1[Month],$A12,Table1[Type],"Purchase") -> 0 | AE12: =SUM(B12:AD12) -> 64607
A13: 2022-10 | B13: =SUMIFS(Table1[Amount],Table1[Customer_ID],B$1,Table1[Month],$A13,Table1[Type],"Purchase") -> 0 | C13: =SUMIFS(Table1[Amount],Table1[Customer_ID],C$1,Table1[Month],$A13,Table1[Type],"Purchase") -> 0 | D13: =SUMIFS(Table1[Amount],Table1[Customer_ID],D$1,Table1[Month],$A13,Table1[Type],"Purchase") -> 7616 | E13: =SUMIFS(Table1[Amount],Table1[Customer_ID],E$1,Table1[Month],$A13,Table1[Type],"Purchase") -> 2499 | F13: =SUMIFS(Table1[Amount],Table1[Customer_ID],F$1,Table1[Month],$A13,Table1[Type],"Purchase") -> 240 | G13: =SUMIFS(Table1[Amount],Table1[Customer_ID],G$1,Table1[Month],$A13,Table1[Type],"Purchase") -> 3473 | H13: =SUMIFS(Table1[Amount],Table1[Customer_ID],H$1,Table1[Month],$A13,Table1[Type],"Purchase") -> 12162 | I13: =SUMIFS(Table1[Amount],Table1[Customer_ID],I$1,Table1[Month],$A13,Table1[Type],"Purchase") -> 441 | ... AD13: =SUMIFS(Table1[Amount],Table1[Customer_ID],AD$1,Table1[Month],$A13,Table1[Type],"Purchase") -> 0 | AE13: =SUM(B13:AD13) -> 85015
... A43: 2025-04 | B43: =SUMIFS(Table1[Amount],Table1[Customer_ID],B$1,Table1[Month],$A43,Table1[Type],"Purchase") -> 0 | C43: =SUMIFS(Table1[Amount],Table1[Customer_ID],C$1,Table1[Month],$A43,Table1[Type],"Purchase") -> 4522 | D43: =SUMIFS(Table1[Amount],Table1[Customer_ID],D$1,Table1[Month],$A43,Table1[Type],"Purchase") -> 0 | E43: =SUMIFS(Table1[Amount],Table1[Customer_ID],E$1,Table1[Month],$A43,Table1[Type],"Purchase") -> 0 | F43: =SUMIFS(Table1[Amount],Table1[Customer_ID],F$1,Table1[Month],$A43,Table1[Type],"Purchase") -> 0 | G43: =SUMIFS(Table1[Amount],Table1[Customer_ID],G$1,Table1[Month],$A43,Table1[Type],"Purchase") -> 0 | H43: =SUMIFS(Table1[Amount],Table1[Customer_ID],H$1,Table1[Month],$A43,Table1[Type],"Purchase") -> 0 | I43: =SUMIFS(Table1[Amount],Table1[Customer_ID],I$1,Table1[Month],$A43,Table1[Type],"Purchase") -> 0 | ... AD43: =SUMIFS(Table1[Amount],Table1[Customer_ID],AD$1,Table1[Month],$A43,Table1[Type],"Purchase") -> 0 | AE43: =SUM(B43:AD43) -> 4522
A44: TOTAL | B44: =SUM(B2:B43) -> 13976 | C44: =SUM(C2:C43) -> 28852 | D44: =SUM(D2:D43) -> 17955 | E44: =SUM(E2:E43) -> 23993 | F44: =SUM(F2:F43) -> 4750 | G44: =SUM(G2:G43) -> 53928 | H44: =SUM(H2:H43) -> 40423 | I44: =SUM(I2:I43) -> 1634 | ... AD44: =SUM(AD2:AD43) -> 23379 | AE44: =SUM(B44:AD44) -> 715682

Sheet Charts
A1: Business question: who is buying less over time? (early warning)
A26: CUST_001 fell from Rs 4,702 (Jan 2025) to Rs 1,621 (Mar 2025) and bought nothing in Apr 2025, while still owing Rs 10,301. CUST_002 stayed between Rs 4,500 and Rs 7,100 a month and owes nothing.
A27: Note: Nov 2024 is the first month in the book for both, so it is a part month.

Sheet Data_Checks
A1: Check | B1: Result | C1: Status | D1: What it means
A2: Total rows in Ledger | B2: =ROWS(Table1[]) -> 3065 | C2: =IF(B2>0,"OK","LOOK") -> OK | D2: Every line from dad's book
A3: Rows with blank Date | B3: =COUNTBLANK(Table1[Date]) -> 110 | C3: =IF(B3=0,"OK","KNOWN") -> KNOWN | D3: Mostly payments where dad wrote no date; they still count in balances
A4: Rows with blank Customer_ID | B4: =COUNTBLANK(Table1[Customer_ID]) -> 0 | C4: =IF(B4=0,"OK","LOOK") -> OK | D4: Every row must belong to a customer
A5: Rows with blank Amount | B5: =COUNTBLANK(Table1[Amount]) -> 0 | C5: =IF(B5=0,"OK","LOOK") -> OK | D5: Every row must have an amount
A6: Purchase rows | B6: =COUNTIFS(Table1[Type],"Purchase") -> 2755
A7: Payment rows | B7: =COUNTIFS(Table1[Type],"Payment") -> 200
A8: Old_Balance rows | B8: =COUNTIFS(Table1[Type],"Old_Balance") -> 26
A9: Adjustment rows | B9: =COUNTIFS(Table1[Type],"Adjustment") -> 84
A10: Rows with any other Type | B10: =B2-SUM(B6:B9) -> 0 | C10: =IF(B10=0,"OK","LOOK") -> OK | D10: Should be 0: every row is one of the 4 types
A11: Total of Adjustments (Rs) | B11: =SUMIFS(Table1[Amount],Table1[Type],"Adjustment") -> -2347 | C11: =IF(ABS(B11)<5000,"OK","LOOK") -> OK | D11: Net money in dad's totals with no written line; small = book is reliable
A12: Yellow CHECK rows | B12: =COUNTIF(Table1[Notes],"CHECK:*") -> 31 | C12: =IF(B12=0,"OK","ASK DAD") -> ASK DAD | D12: Unclear entries to confirm with dad (notes starting 'CHECK:'; 'Checked' notes are already confirmed)
A13: Purchases below zero | B13: =COUNTIFS(Table1[Type],"Purchase",Table1[Amount],"<0") -> 0 | C13: =IF(B13=0,"OK","LOOK") -> OK | D13: A purchase can never be negative
A14: Customer IDs not in Customers sheet | B14: =COUNTIF(Table1[Customer_Type],"Not found") -> 0 | C14: =IF(B14=0,"OK","LOOK") -> OK | D14: XLOOKUP found a type for every row
A15: Earliest date | B15: =MIN(Table1[Date]) -> 44520
A16: Latest date | B16: =MAX(Table1[Date]) -> 45759
A17: Purchases: Ledger total (Rs) | B17: =SUMIFS(Table1[Amount],Table1[Type],"Purchase") -> 715682
A18: Purchases: Customer_Summary total (Rs) | B18: =Customer_Summary!B32 -> 715682 | C18: =IF(B18=B17,"OK","LOOK") -> OK | D18: Two methods give the same total
A19: Purchases: Monthly_Purchases total (Rs) | B19: =Monthly_Purchases!AE44 -> 715682 | C19: =IF(B19=B17,"OK","LOOK") -> OK | D19: No purchase row is missing a month
A20: Total owed by all customers now (Rs) | B20: =Customer_Summary!F32 -> 125321 | D20: Money the shop is waiting to collect

Sheet How_it_works
A1: Where | B1: Formula (row 2) | C1: In plain English | D1: Business question
A2: Top_Customers (pivot) | B2: Show Values As > % of Grand Total | C2: Each customer's purchases as a share of all purchases | D2: How much does the shop depend on its biggest customers?
A3: Customer_Summary B Total_Bought | B3: =SUMIFS(Table1[Amount],Table1[Customer_ID],A2,Table1[Type],"Purchase") | C3: Add Amount where Customer_ID = this customer AND Type = Purchase | D3: How much has each customer bought?
A4: Customer_Summary C Total_Paid | B4: =SUMIFS(Table1[Amount],Table1[Customer_ID],A2,Table1[Type],"Payment") | C4: Same, but Type = Payment | D4: How much has each customer paid?
A5: Customer_Summary D Old_Balance | B5: =SUMIFS(... "Old_Balance") | C5: Dues already owed when dad started a page/book | D5: How much was owed before our data starts?
A6: Customer_Summary E Adjustments | B6: =SUMIFS(... "Adjustment") | C6: Amounts in dad's totals with no written line (can be minus) | D6: Does our balance match dad's book?
A7: Customer_Summary F Owes_Now | B7: =D2+B2+E2-C2 | C7: Old balance + bought + adjustments - paid | D7: Who owes the most right now?
A8: Customer_Summary G Pct_Paid | B8: =IFERROR(C2/(B2+D2+E2),0) | C8: Paid / everything billed. IFERROR shows 0 instead of an error if nothing was billed. Red if below 70% (Conditional Formatting) | D8: Who pays in full vs who keeps a balance?
A9: Customer_Summary H Share_of_Sales | B9: =B2/SUM($B$2:$B$28) | C9: This customer's purchases / all purchases. $ locks the range so it does not move when filled down | D9: Concentration risk, same as the pivot
A10: Customer_Summary I Purchase_Entries | B10: =COUNTIFS(Table1[Customer_ID],A2,Table1[Type],"Purchase") | C10: COUNT rows (not add) that match both conditions | D10: How often does each customer buy?
A11: Customer_Summary J Last_Purchase | B11: =MAXIFS(Table1[Date],Table1[Customer_ID],A2,Table1[Type],"Purchase") | C11: Latest date among this customer's purchases | D11: Who has stopped coming?
A12: Customer_Summary K Customer_Type | B12: =XLOOKUP(A2,Customers!$A$2:$A$28,Customers!$D$2:$D$28,"Not found") | C12: Find A2 in the Customers ID list, return the type from the same row | D12: Does dad's label match the numbers?
... A17: Data_Checks | B17: COUNTBLANK, COUNTIF, ROWS, MIN, MAX | C17: Count blanks, count CHECK notes, compare totals from 3 methods | D17: Can we trust the data before analysing it?
A19: KEY FINDINGS
A20: 1 | C20: CUST_027 = 20.9% of credit purchases; top 5 customers = 47.9%
A21: 2 | C21: Customers owe Rs 1,15,826 in total. Biggest: CUST_013 16,273, CUST_019 13,007, CUST_001 10,301
A22: 3 | C22: Overall 85.3% of everything billed has been paid. 7 customers have paid less than 70% (red in column G)
A23: 4 | C23: CUST_007, CUST_015 and CUST_018 are labelled 'Pays full' but still owe 9,084 / 4,109 / 3,172 - ask dad
A24: 5 | C24: CUST_001 purchases fell from Rs 4,702 (Jan 2025) to Rs 1,621 (Mar 2025) and stopped in Apr 2025 while owing Rs 10,301

Sheet Ledger
A1: Date | B1: Customer_ID | C1: Type | D1: Amount | E1: Written_Balance | F1: Page_No | G1: Notes | H1: Month | I1: Customer_Type
A2: 45626 | B2: CUST_001 | C2: Purchase | D2: 202 | F2: 82 | G2: Opening balance 0: earlier BAKI 985 was paid before 30/11 | H2: =IF(A2="","",TEXT(A2,"yyyy-mm")) -> 2024-11 | I2: =_xlfn.XLOOKUP(Table1[[#This Row],[Customer_ID]],Customers!$A$2:$A$30,Customers!$C$2:$C$30,"Not found") -> Carries forward
A3: 45626 | B3: CUST_001 | C3: Purchase | D3: 100 | F3: 82 | H3: =IF(A3="","",TEXT(A3,"yyyy-mm")) -> 2024-11 | I3: =_xlfn.XLOOKUP(Table1[[#This Row],[Customer_ID]],Customers!$A$2:$A$30,Customers!$C$2:$C$30,"Not found") -> Carries forward
A4: 45628 | B4: CUST_001 | C4: Purchase | D4: 70 | F4: 82 | H4: =IF(A4="","",TEXT(A4,"yyyy-mm")) -> 2024-12 | I4: =_xlfn.XLOOKUP(Table1[[#This Row],[Customer_ID]],Customers!$A$2:$A$30,Customers!$C$2:$C$30,"Not found") -> Carries forward
A5: 45631 | B5: CUST_001 | C5: Purchase | D5: 2348 | F5: 82 | G5: Checked in book | H5: =IF(A5="","",TEXT(A5,"yyyy-mm")) -> 2024-12 | I5: =_xlfn.XLOOKUP(Table1[[#This Row],[Customer_ID]],Customers!$A$2:$A$30,Customers!$C$2:$C$30,"Not found") -> Carries forward
A6: 45634 | B6: CUST_001 | C6: Purchase | D6: 79 | F6: 82 | H6: =IF(A6="","",TEXT(A6,"yyyy-mm")) -> 2024-12 | I6: =_xlfn.XLOOKUP(Table1[[#This Row],[Customer_ID]],Customers!$A$2:$A$30,Customers!$C$2:$C$30,"Not found") -> Carries forward
A7: 45634 | B7: CUST_001 | C7: Purchase | D7: 13 | F7: 82 | H7: =IF(A7="","",TEXT(A7,"yyyy-mm")) -> 2024-12 | I7: =_xlfn.XLOOKUP(Table1[[#This Row],[Customer_ID]],Customers!$A$2:$A$30,Customers!$C$2:$C$30,"Not found") -> Carries forward
A8: 45634 | B8: CUST_001 | C8: Purchase | D8: 110 | F8: 82 | H8: =IF(A8="","",TEXT(A8,"yyyy-mm")) -> 2024-12 | I8: =_xlfn.XLOOKUP(Table1[[#This Row],[Customer_ID]],Customers!$A$2:$A$30,Customers!$C$2:$C$30,"Not found") -> Carries forward
A9: 45637 | B9: CUST_001 | C9: Purchase | D9: 15 | F9: 82 | G9: Checked in book | H9: =IF(A9="","",TEXT(A9,"yyyy-mm")) -> 2024-12 | I9: =_xlfn.XLOOKUP(Table1[[#This Row],[Customer_ID]],Customers!$A$2:$A$30,Customers!$C$2:$C$30,"Not found") -> Carries forward
A10: 45642 | B10: CUST_001 | C10: Purchase | D10: 142 | F10: 82 | H10: =IF(A10="","",TEXT(A10,"yyyy-mm")) -> 2024-12 | I10: =_xlfn.XLOOKUP(Table1[[#This Row],[Customer_ID]],Customers!$A$2:$A$30,Customers!$C$2:$C$30,"Not found") -> Carries forward
A11: 45643 | B11: CUST_001 | C11: Purchase | D11: 553 | E11: 3632 | F11: 82 | G11: Book: Tot 3632 | H11: =IF(A11="","",TEXT(A11,"yyyy-mm")) -> 2024-12 | I11: =_xlfn.XLOOKUP(Table1[[#This Row],[Customer_ID]],Customers!$A$2:$A$30,Customers!$C$2:$C$30,"Not found") -> Carries forward
A12: 45644 | B12: CUST_001 | C12: Purchase | D12: 60 | E12: 3692 | F12: 82 | G12: Book: Tot 3692 | H12: =IF(A12="","",TEXT(A12,"yyyy-mm")) -> 2024-12 | I12: =_xlfn.XLOOKUP(Table1[[#This Row],[Customer_ID]],Customers!$A$2:$A$30,Customers!$C$2:$C$30,"Not found") -> Carries forward
A13: 45644 | B13: CUST_001 | C13: Purchase | D13: 10 | F13: 82 | H13: =IF(A13="","",TEXT(A13,"yyyy-mm")) -> 2024-12 | I13: =_xlfn.XLOOKUP(Table1[[#This Row],[Customer_ID]],Customers!$A$2:$A$30,Customers!$C$2:$C$30,"Not found") -> Carries forward
A14: 45645 | B14: CUST_001 | C14: Purchase | D14: 259 | F14: 82 | H14: =IF(A14="","",TEXT(A14,"yyyy-mm")) -> 2024-12 | I14: =_xlfn.XLOOKUP(Table1[[#This Row],[Customer_ID]],Customers!$A$2:$A$30,Customers!$C$2:$C$30,"Not found") -> Carries forward
A15: 45645 | B15: CUST_001 | C15: Purchase | D15: 75 | E15: 4036 | F15: 82 | G15: Book: total 4036 | H15: =IF(A15="","",TEXT(A15,"yyyy-mm")) -> 2024-12 | I15: =_xlfn.XLOOKUP(Table1[[#This Row],[Customer_ID]],Customers!$A$2:$A$30,Customers!$C$2:$C$30,"Not found") -> Carries forward
A16: 45657 | B16: CUST_001 | C16: Payment | D16: 3000 | E16: 1036 | F16: 82 | G16: Checked in book: 31/12. 4036 - 3000 = 1036 | H16: =IF(A16="","",TEXT(A16,"yyyy-mm")) -> 2024-12 | I16: =_xlfn.XLOOKUP(Table1[[#This Row],[Customer_ID]],Customers!$A$2:$A$30,Customers!$C$2:$C$30,"Not found") -> Carries forward
A17: 45657 | B17: CUST_001 | C17: Purchase | D17: 420 | F17: 82 | H17: =IF(A17="","",TEXT(A17,"yyyy-mm")) -> 2024-12 | I17: =_xlfn.XLOOKUP(Table1[[#This Row],[Customer_ID]],Customers!$A$2:$A$30,Customers!$C$2:$C$30,"Not found") -> Carries forward
A18: 45657 | B18: CUST_001 | C18: Purchase | D18: 30 | F18: 82 | H18: =IF(A18="","",TEXT(A18,"yyyy-mm")) -> 2024-12 | I18: =_xlfn.XLOOKUP(Table1[[#This Row],[Customer_ID]],Customers!$A$2:$A$30,Customers!$C$2:$C$30,"Not found") -> Carries forward
A19: 45658 | B19: CUST_001 | C19: Purchase | D19: 80 | F19: 82 | H19: =IF(A19="","",TEXT(A19,"yyyy-mm")) -> 2025-01 | I19: =_xlfn.XLOOKUP(Table1[[#This Row],[Customer_ID]],Customers!$A$2:$A$30,Customers!$C$2:$C$30,"Not found") -> Carries forward
A20: 45661 | B20: CUST_001 | C20: Purchase | D20: 388 | F20: 82 | H20: =IF(A20="","",TEXT(A20,"yyyy-mm")) -> 2025-01 | I20: =_xlfn.XLOOKUP(Table1[[#This Row],[Customer_ID]],Customers!$A$2:$A$30,Customers!$C$2:$C$30,"Not found") -> Carries forward
A21: 45663 | B21: CUST_001 | C21: Purchase | D21: 55 | F21: 82 | H21: =IF(A21="","",TEXT(A21,"yyyy-mm")) -> 2025-01 | I21: =_xlfn.XLOOKUP(Table1[[#This Row],[Customer_ID]],Customers!$A$2:$A$30,Customers!$C$2:$C$30,"Not found") -> Carries forward
A22: 45664 | B22: CUST_001 | C22: Purchase | D22: 190 | F22: 82 | H22: =IF(A22="","",TEXT(A22,"yyyy-mm")) -> 2025-01 | I22: =_xlfn.XLOOKUP(Table1[[#This Row],[Customer_ID]],Customers!$A$2:$A$30,Customers!$C$2:$C$30,"Not found") -> Carries forward
A23: 45665 | B23: CUST_001 | C23: Purchase | D23: 160 | F23: 82 | H23: =IF(A23="","",TEXT(A23,"yyyy-mm")) -> 2025-01 | I23: =_xlfn.XLOOKUP(Table1[[#This Row],[Customer_ID]],Customers!$A$2:$A$30,Customers!$C$2:$C$30,"Not found") -> Carries forward
A24: 45667 | B24: CUST_001 | C24: Purchase | D24: 194 | F24: 82 | H24: =IF(A24="","",TEXT(A24,"yyyy-mm")) -> 2025-01 | I24: =_xlfn.XLOOKUP(Table1[[#This Row],[Customer_ID]],Customers!$A$2:$A$30,Customers!$C$2:$C$30,"Not found") -> Carries forward
A25: 45669 | B25: CUST_001 | C25: Purchase | D25: 889 | F25: 82 | H25: =IF(A25="","",TEXT(A25,"yyyy-mm")) -> 2025-01 | I25: =_xlfn.XLOOKUP(Table1[[#This Row],[Customer_ID]],Customers!$A$2:$A$30,Customers!$C$2:$C$30,"Not found") -> Carries forward
A26: 45669 | B26: CUST_001 | C26: Purchase | D26: 74 | F26: 82 | G26: Checked in book | H26: =IF(A26="","",TEXT(A26,"yyyy-mm")) -> 2025-01 | I26: =_xlfn.XLOOKUP(Table1[[#This Row],[Customer_ID]],Customers!$A$2:$A$30,Customers!$C$2:$C$30,"Not found") -> Carries forward
A27: 45671 | B27: CUST_001 | C27: Purchase | D27: 252 | F27: 82 | G27: Set to 252: matches dad's totals 3778 and 6080 | H27: =IF(A27="","",TEXT(A27,"yyyy-mm")) -> 2025-01 | I27: =_xlfn.XLOOKUP(Table1[[#This Row],[Customer_ID]],Customers!$A$2:$A$30,Customers!$C$2:$C$30,"Not found") -> Carries forward
A28: 45672 | B28: CUST_001 | C28: Purchase | D28: 10 | E28: 3778 | F28: 82 | G28: Book: circled 3778 (includes 1036 carried forward) | H28: =IF(A28="","",TEXT(A28,"yyyy-mm")) -> 2025-01 | I28: =_xlfn.XLOOKUP(Table1[[#This Row],[Customer_ID]],Customers!$A$2:$A$30,Customers!$C$2:$C$30,"Not found") -> Carries forward
A29: 45674 | B29: CUST_001 | C29: Purchase | D29: 262 | F29: 82 | H29: =IF(A29="","",TEXT(A29,"yyyy-mm")) -> 2025-01 | I29: =_xlfn.XLOOKUP(Table1[[#This Row],[Customer_ID]],Customers!$A$2:$A$30,Customers!$C$2:$C$30,"Not found") -> Carries forward
A30: 45674 | B30: CUST_001 | C30: Purchase | D30: 88 | F30: 82 | H30: =IF(A30="","",TEXT(A30,"yyyy-mm")) -> 2025-01 | I30: =_xlfn.XLOOKUP(Table1[[#This Row],[Customer_ID]],Customers!$A$2:$A$30,Customers!$C$2:$C$30,"Not found") -> Carries forward
A31: 45674 | B31: CUST_001 | C31: Purchase | D31: 70 | F31: 82 | H31: =IF(A31="","",TEXT(A31,"yyyy-mm")) -> 2025-01 | I31: =_xlfn.XLOOKUP(Table1[[#This Row],[Customer_ID]],Customers!$A$2:$A$30,Customers!$C$2:$C$30,"Not found") -> Carries forward
A32: 45677 | B32: CUST_001 | C32: Purchase | D32: 328 | F32: 82 | H32: =IF(A32="","",TEXT(A32,"yyyy-mm")) -> 2025-01 | I32: =_xlfn.XLOOKUP(Table1[[#This Row],[Customer_ID]],Customers!$A$2:$A$30,Customers!$C$2:$C$30,"Not found") -> Carries forward
A33: 45678 | B33: CUST_001 | C33: Purchase | D33: 20 | F33: 82 | H33: =IF(A33="","",TEXT(A33,"yyyy-mm")) -> 2025-01 | I33: =_xlfn.XLOOKUP(Table1[[#This Row],[Customer_ID]],Customers!$A$2:$A$30,Customers!$C$2:$C$30,"Not found") -> Carries forward
A34: 45679 | B34: CUST_001 | C34: Purchase | D34: 185 | F34: 82 | H34: =IF(A34="","",TEXT(A34,"yyyy-mm")) -> 2025-01 | I34: =_xlfn.XLOOKUP(Table1[[#This Row],[Customer_ID]],Customers!$A$2:$A$30,Customers!$C$2:$C$30,"Not found") -> Carries forward
A35: 45680 | B35: CUST_001 | C35: Purchase | D35: 201 | F35: 82 | H35: =IF(A35="","",TEXT(A35,"yyyy-mm")) -> 2025-01 | I35: =_xlfn.XLOOKUP(Table1[[#This Row],[Customer_ID]],Customers!$A$2:$A$30,Customers!$C$2:$C$30,"Not found") -> Carries forward
A36: 45681 | B36: CUST_001 | C36: Purchase | D36: 67 | F36: 82 | H36: =IF(A36="","",TEXT(A36,"yyyy-mm")) -> 2025-01 | I36: =_xlfn.XLOOKUP(Table1[[#This Row],[Customer_ID]],Customers!$A$2:$A$30,Customers!$C$2:$C$30,"Not found") -> Carries forward
A37: 45682 | B37: CUST_001 | C37: Purchase | D37: 395 | F37: 82 | H37: =IF(A37="","",TEXT(A37,"yyyy-mm")) -> 2025-01 | I37: =_xlfn.XLOOKUP(Table1[[#This Row],[Customer_ID]],Customers!$A$2:$A$30,Customers!$C$2:$C$30,"Not found") -> Carries forward
A38: 45684 | B38: CUST_001 | C38: Purchase | D38: 13 | F38: 82 | H38: =IF(A38="","",TEXT(A38,"yyyy-mm")) -> 2025-01 | I38: =_xlfn.XLOOKUP(Table1[[#This Row],[Customer_ID]],Customers!$A$2:$A$30,Customers!$C$2:$C$30,"Not found") -> Carries forward
A39: 45685 | B39: CUST_001 | C39: Purchase | D39: 673 | E39: 6080 | F39: 82 | G39: Book: Tot 6080. Side note 2302 = total of 17/1 to 28/1 (6080 - 3778) | H39: =IF(A39="","",TEXT(A39,"yyyy-mm")) -> 2025-01 | I39: =_xlfn.XLOOKUP(Table1[[#This Row],[Customer_ID]],Customers!$A$2:$A$30,Customers!$C$2:$C$30,"Not found") -> Carries forward
A40: 45688 | B40: CUST_001 | C40: Purchase | D40: 98 | F40: 82 | G40: Checked in book | H40: =IF(A40="","",TEXT(A40,"yyyy-mm")) -> 2025-01 | I40: =_xlfn.XLOOKUP(Table1[[#This Row],[Customer_ID]],Customers!$A$2:$A$30,Customers!$C$2:$C$30,"Not found") -> Carries forward
...

Sheet Customers
A1: Customer_ID | B1: Customer_Since | C1: Pays_Full_or_Carries | D1: Notes | E1: Account_No
A2: CUST_001 | C2: Carries forward | D2: Pages 82-83. Last entry 27/03/2025. Visits and spend fell Jan-Mar; payments 3000, 3000, 1500 | E2: 37
A3: CUST_002 | C3: Pays full | D3: Pages 114-115. Pays each month in full (small round-offs let go) | E3: 54
A4: CUST_003 | C4: Carries forward | D4: Pages 268-269, Sep-Dec 2022. Pays big chunks (6000, 7000, 3000, 2000) | E4: 127
A5: CUST_004 | C5: Carries forward | D5: Pages 270-271, Sep 2022-Mar 2023. Pays 1000-5000 at a time, balance stays high | E5: 128
A6: CUST_005 | C6: Carries forward | D6: Pages 282-283, Oct 2022-Apr 2023. Small daily buys (10-40), pays 500-1200 | E6: 134
A7: CUST_006 | C7: Mixed | D7: Pages 204 (2022, acct 95) and 316-317 (2023, acct 151). Paid in full most months, old 2633 owed in 2023 | E7: 151, 95
A8: CUST_007 | C8: Pays full | D8: Pages 206-207, Sep-Dec 2022. Big totals (9-15k) paid in full | E8: 96
A9: CUST_008 | C9: Carries forward | D9: Small account on page 205, Sep 2022-Jan 2023. Buys 10-80, pays 200-688 | E9: none (p205)
A10: CUST_009 | C10: Carries forward | D10: Small account on page 205, Sep 2022. Owes 831, no payment seen | E10: none (p205)
A11: CUST_010 | C11: Mixed | D11: Page 219, Sep 2022-Jun 2023. Pays most of each bill, leaves small balance | E11: 100
A12: CUST_011 | C12: Pays full | D12: Pages 244-245, Sep 2022-Apr 2023 | E12: 115
A13: CUST_012 | C13: Carries forward | D13: Page 238, Mar-Jul 2024. Daily small buys, lump payments | E13: 113
A14: CUST_013 | C14: Carries forward | D14: Pages 236-237, Mar-May 2024. Very heavy buyer, owes ~16k | E14: 114
A15: CUST_014 | C15: Carries forward | D15: Page 230, Feb-Jul 2024. Pays part each month | E15: 111
A16: CUST_015 | C16: Pays full | D16: Pages 178-179, Dec 2023-Jul 2024 | E16: 85
A17: CUST_016 | C17: Mixed | D17: Pages 228-229, Sep 2022-2023. Settled fully at the end | E17: 107
A18: CUST_017 | C18: Carries forward | D18: Pages 226-227, Sep 2022-Feb 2023. Big balance 8-10k carried. Page 326 (acct 156) skipped, blurry | E18: 106, 156
A19: CUST_018 | C19: Pays full | D19: Page 234, Sep 2022-May 2023 | E19: 110
A20: CUST_019 | C20: Carries forward | D20: Pages 224-225, Sep 2022-Jun 2023. Very large, pays 5-8k chunks | E20: 105
A21: CUST_020 | C21: Carries forward | D21: Pages 222-223, Sep-Dec 2022. Pays in big chunks | E21: 104
A22: CUST_021 | C22: Carries forward | D22: Pages 220-221, Sep 2022-Mar 2023. Many 500 instalments | E22: 103
A23: CUST_022 | C23: Carries forward | D23: Sep 2022-Jan 2023. Dad charged INTEREST (int 200) | E23: 69
A24: CUST_023 | C24: Mixed | D24: Page 150, Sep 2022-May 2023. Few big buys, regular payments | E24: 68
A25: CUST_024 | C25: Mixed | D25: Page 126, ~Nov 2021-Jun 2022 (year inferred) | E25: 56
A26: CUST_025 | C26: Carries forward | D26: Page 74, Sep 2022-Apr 2023. Balance growing to 6830 | E26: 30
A27: CUST_026 | C27: Mixed | D27: Page 140, Sep 2022-Jun 2023. Big buyer, pays 5-6.5k | E27: 63
A28: CUST_027 | C28: Mixed | D28: Pages 188-189 (2022-23, acct 87) and 112-113 (2023-24, acct 52). Business-size buyer. Balance is per book: older book ended 1042 in Feb 2023 | E28: 52, 87
A29: CUST_028 | C29: Pays full | D29: Page 200, Nov 2024-Feb 2025. Old dues 2858; paid 4500 (7/12) and 3200 (Jan). 4th column (25/1-7/2) cut off in photo - retake | E29: 97
A30: CUST_029 | C30: Pays full | D30: Page 244, Dec 2024-Feb 2025. Big buyer (rice, gas). Paid Dec total 9093 and Jan total 7238 in full. Acct number unclear (114?) | E30: 114?

Sheet Example
A1: EXAMPLE ONLY - made-up rows showing how to fill the Ledger sheet
A2: Date | B2: Customer_ID | C2: Type | D2: Amount | E2: Written_Balance | F2: Page_No | G2: Notes
A3: 45567 | B3: CUST_001 | C3: Purchase | D3: 240 | F3: 1
A4: 45567 | B4: CUST_001 | C4: Purchase | D4: 60 | F4: 1 | G4: came twice same day = 2 rows
A5: 45570 | B5: CUST_001 | C5: Purchase | D5: 415 | F5: 1
A6: 45584 | B6: CUST_001 | C6: Purchase | D6: 380 | E6: 1095 | F6: 1 | G6: balance written because customer asked
A7: 45599 | B7: CUST_001 | C7: Payment | D7: 800 | F7: 2 | G7: paid part
A8: 45599 | B8: CUST_001 | C8: Purchase | D8: 150 | E8: 445 | F8: 2 | G8: dad wrote leftover balance after payment
